<mujoco>    
    <worldbody>
        <camera name="maincam" mode= "fixed" fovy="75" euler="0 0 0" pos="0 0 .75"/>
        <body name="particle" pos="0 0 0.03">
            <inertial pos="0 0 0" mass="5" diaginertia="166.667 166.667 166.667"/>
            <geom name="particle_geom" type="capsule" fromto="-0.01 0 0 0.01 0 0" size="0.05" rgba="0.9 0 0.1 0.6" />
            <joint name="ball_x" type="slide" pos="0 0 0" axis="1 0 0" />
            <joint name="ball_y" type="slide" pos="0 0 0" axis="0 1 0" />
            <site name="sensorsurf" pos="0 0.045 0" size=".03 .03 .03" type="ellipsoid" rgba="0.3 0.2 0.1 0.3"/>

        </body>

    </worldbody>

     <sensor>
         <touch name="touchsensor" site="sensorsurf" />
     </sensor>
</mujoco>